Workbook

Sheet Outputs
B22: Apple Inc.
B23: DCF Valuation & 3-Statement Model ( Valuation date: 1/1/2026 )
B25: Prepared by: Bruuno Heikkinen
B27: 1. | C27: Valuation summary & scenario analysis
B28: 2. | C28: Implied share price sensitivity analysis
B29: 3. | C29: Model inputs
B30: 4. | C30: 3-statement model
B31: 5. | C31: DCF model
B32: 6. | C32: Supporting schedules & calculations
B37: Valuation summary & scenario analysis
B39: Equity per share expressed in USD, all other figures in USD millions | I39: Key valuation assumptions
I40: WACC | K40: 0.0882
B41: 3 | I41: Terminal growth | K41: 0.025
I42: Terminal multiple | K42: 16.52
I43: Net debt | K43: =Model!D171 -> 62723
I44: Shares outstanding | K44: 14860
B47: Perpetuity method | H47: Multiple method
D50: Enterprise value | E50: Equity value | F50: Equity per share | J50: Enterprise value | K50: Equity value | L50: Equity per share
D51: =Model!D173 -> 2710540.7 | J51: =Model!D197 -> 3267528.9
B52: Bear case | C52: 1 | D52: 1997022.9 | E52: =$D52-$K$43 -> 1934299.9 | F52: =E52/$K$44 -> 130.16823 | H52: Bear case | I52: 1 | J52: 2388102.8 | K52: =J52-$K$43 -> 2325379.8 | L52: =K52/$K$44 -> 156.48585
B53: Base case | C53: 2 | D53: 2268933.7 | E53: =$D53-$K$43 -> 2206210.7 | F53: =E53/$K$44 -> 148.4664 | H53: Base case | I53: 2 | J53: 2723235.9 | K53: =J53-$K$43 -> 2660512.9 | L53: =K53/$K$44 -> 179.03855
B54: Bull case | C54: 3 | D54: 2710540.7 | E54: =$D54-$K$43 -> 2647817.7 | F54: =E54/$K$44 -> 178.18424 | H54: Bull case | I54: 3 | J54: 3267528.9 | K54: =J54-$K$43 -> 3204805.9 | L54: =K54/$K$44 -> 215.66662
B57: Implied Valuation Range – Football Field Chart
O59: Invisible | P59: Width
N60: Perpetuity | O60: =O66 -> 130.16823 | P60: =O68-O66 -> 48.016003
N61: Multiple | O61: =O72 -> 156.48585 | P61: =O74-O72 -> 59.180762
O64: perpetuity
O65: =Model!J178 -> 178.18424
N66: 1 | O66: 130.16823
N67: 2 | O67: 148.4664
N68: 3 | O68: 178.18424
O70: multiple
O71: =Model!J201 -> 215.66662
N72: 1 | O72: 156.48585
N73: 2 | O73: 179.03855
N74: 3 | O74: 215.66662
B82: Implied share price sensitivity analysis
E85: Current share price | G85: =Inputs!F48 -> 271 | I85: BUY | J85: SELL
B88: Perpetuity method
G90: Terminal growth
...

Sheet Inputs
B3: Inputs
B5: Drivers
B7: =Outputs!B41 -> 3 | F7: 2023 | G7: 2024 | H7: 2025 | I7: 2026F | J7: 2027F | K7: 2028F | L7: 2029F | M7: 2030F | N7: 2031F | O7: term
B10: Revenue growth % | F10: -0.028 | G10: 0.0202 | H10: 0.0643 | I10: =CHOOSE($B$7,I13,I14,I15) -> 0.074 | J10: =CHOOSE($B$7,J13,J14,J15) -> 0.078 | K10: =CHOOSE($B$7,K13,K14,K15) -> 0.082 | L10: =CHOOSE($B$7,L13,L14,L15) -> 0.085 | M10: =CHOOSE($B$7,M13,M14,M15) -> 0.09 | N10: =CHOOSE($B$7,N13,N14,N15) -> 0.0915 | O10: =F46 -> 0.025
B13: Bear case | I13: 0.045 | J13: 0.032 | K13: 0.028 | L13: 0.015 | M13: 0.008 | N13: 0.001
B14: Base case | I14: 0.0571 | J14: 0.05 | K14: 0.0471 | L14: 0.0445 | M14: 0.0427 | N14: 0.042
B15: Bull case | I15: 0.074 | J15: 0.078 | K15: 0.082 | L15: 0.085 | M15: 0.09 | N15: 0.0915
B19: Assumptions
B22: Research & Development % of revenue | F22: 0.08 | G22: 0.08 | H22: 0.08 | I22: 0.08 | J22: 0.08 | K22: 0.08 | L22: 0.08 | M22: 0.08 | N22: 0.08 | O22: 0.08
B24: SG&A % of revenue | F24: 0.07 | G24: 0.07 | H24: 0.07 | I24: 0.07 | J24: 0.07 | K24: 0.07 | L24: 0.07 | M24: 0.07 | N24: 0.07 | O24: 0.07
B26: Gross margin % | F26: 0.433 | G26: 0.462 | H26: 0.469 | I26: 0.473 | J26: 0.479 | K26: 0.484 | L26: 0.49 | M26: 0.504 | N26: 0.509 | O26: 0.51
B28: Days in year | F28: 365 | G28: 365 | H28: 365 | I28: 365 | J28: 365 | K28: 365 | L28: 365 | M28: 365 | N28: 365 | O28: 365
B30: Accounts payable (days) | F30: 107 | G30: 120 | H30: 115 | I30: 115 | J30: 115 | K30: 115 | L30: 115 | M30: 115 | N30: 115 | O30: 115
B31: Account receivable (days) | F31: 28 | G31: 31 | H31: 35 | I31: 32 | J31: 32 | K31: 32 | L31: 32 | M31: 32 | N31: 32 | O31: 32
B32: inventory (days) | F32: 11 | G32: 13 | H32: 9 | I32: 9 | J32: 9 | K32: 9 | L32: 9 | M32: 9 | N32: 9 | O32: 9
B35: D&A % of revenue | F35: 0.028
B36: Capital expenditure % of revenue | F36: 0.03
F37: 0.155
B38: Divident yearly growth % | F38: 0.013
B39: Buybacks of common stock per year | F39: 100000
B44: Valuation assumptions
B46: Terminal growth rate | F46: =Outputs!K41 -> 0.025
B47: Shares outstanding | F47: =Outputs!K44 -> 14860
B48: current share price | F48: 271
B49: EV / EBITDA multiple | F49: =Outputs!K42 -> 16.52
B50: Valuation date | F50: 46023
B51: WACC | F51: =Outputs!K40 -> 0.0882
B53: WACC
K55: Sources
B56: Risk-free rate | F56: 0.0436
B57: Equity risk premium | F57: 0.0424 | K57: Damodaran
B59: Calculated beta = Industry unlevered beta x (1+ (D/E) x (1 - tax rate))
B60: Industry unlevered beta | F60: 0.83 | K60: Damodaran
B61: Debt | F61: 291.11 | G61: (Billions of dollars) | K61: macrotrends
B62: Market cap | F62: 4032.15 | G62: (Billions of dollars) | K62: macrotrends
B63: D/E | F63: =F61/F62 -> 0.072197215
B64: tax rate | F64: =F37 -> 0.155 | K64: this model
B66: Calculated beta | F66: =F60*(1+F63*(1-F64)) -> 0.88063552
B67: Historical beta | F67: 1.07 | K67: Yahoo finance
B70: Beta used in the model | F70: =CHOOSE(K70,F66,F67) -> 1.07 | I70: beta switch: | K70: 2
...

Sheet Model
B2: 3-statement model
B5: Income Statement
B7: All figures in USD millions unless stated | F7: 2023 | G7: 2024 | H7: 2025 | I7: 2026F | J7: 2027F | K7: 2028F | L7: 2029F | M7: 2030F | N7: 2031F | O7: term
B10: Gross margin % | F10: =Inputs!F26 -> 0.433 | G10: =Inputs!G26 -> 0.462 | H10: =Inputs!H26 -> 0.469 | I10: =Inputs!I26 -> 0.473 | J10: =Inputs!J26 -> 0.479 | K10: =Inputs!K26 -> 0.484 | L10: =Inputs!L26 -> 0.49 | M10: =Inputs!M26 -> 0.504 | ... O10: =Inputs!O26 -> 0.51
B11: R&D % | F11: =Inputs!F22 -> 0.08 | G11: =Inputs!G22 -> 0.08 | H11: =Inputs!H22 -> 0.08 | I11: =Inputs!I22 -> 0.08 | J11: =Inputs!J22 -> 0.08 | K11: =Inputs!K22 -> 0.08 | L11: =Inputs!L22 -> 0.08 | M11: =Inputs!M22 -> 0.08 | ... O11: =Inputs!O22 -> 0.08
B12: SG&A % | F12: =Inputs!F24 -> 0.07 | G12: =Inputs!G24 -> 0.07 | H12: =Inputs!H24 -> 0.07 | I12: =Inputs!I24 -> 0.07 | J12: =Inputs!J24 -> 0.07 | K12: =Inputs!K24 -> 0.07 | L12: =Inputs!L24 -> 0.07 | M12: =Inputs!M24 -> 0.07 | ... O12: =Inputs!O24 -> 0.07
B15: revenue | F15: 383285 | G15: 391035 | H15: 416161 | I15: =H15*(1+Inputs!I10) -> 446956.91 | J15: =I15*(1+Inputs!J10) -> 481819.55 | K15: =J15*(1+Inputs!K10) -> 521328.76 | L15: =K15*(1+Inputs!L10) -> 565641.7 | M15: =L15*(1+Inputs!M10) -> 616549.45 | N15: =M15*(1+Inputs!N10) -> 672963.73 | O15: =N15*(1+Inputs!O10) -> 689787.82
B16: COGS | F16: -214137 | G16: -210352 | H16: -220960 | I16: =(I15-I17)*-1 -> -235546.29 | J16: =(J15-J17)*-1 -> -251027.99 | K16: =(K15-K17)*-1 -> -269005.64 | L16: =(L15-L17)*-1 -> -288477.27 | M16: =(M15-M17)*-1 -> -305808.53 | N16: =(N15-N17)*-1 -> -330425.19 | O16: =(O15-O17)*-1 -> -337996.03
B17: Gross profit | F17: =F15+F16 -> 169148 | G17: =G15+G16 -> 180683 | H17: =H15+H16 -> 195201 | I17: =I15*I10 -> 211410.62 | J17: =J15*J10 -> 230791.57 | K17: =K15*K10 -> 252323.12 | L17: =L15*L10 -> 277164.43 | M17: =M15*M10 -> 310740.92 | N17: =N15*N10 -> 342538.54 | O17: =O15*O10 -> 351791.79
B19: Operating expenses:
B20: Research and development | F20: -29915 | G20: -31370 | H20: -34550 | I20: =I15*I11*-1 -> -35756.553 | J20: =J15*J11*-1 -> -38545.564 | K20: =K15*K11*-1 -> -41706.301 | L20: =L15*L11*-1 -> -45251.336 | M20: =M15*M11*-1 -> -49323.956 | N20: =N15*N11*-1 -> -53837.098 | O20: =O15*O11*-1 -> -55183.026
B21: Selling, general and administrative | F21: -24932 | G21: -26097 | H21: -27601 | I21: =I15*I12*-1 -> -31286.984 | J21: =J15*J12*-1 -> -33727.369 | K21: =K15*K12*-1 -> -36493.013 | L21: =L15*L12*-1 -> -39594.919 | M21: =M15*M12*-1 -> -43158.462 | N21: =N15*N12*-1 -> -47107.461 | O21: =O15*O12*-1 -> -48285.148
B22: Total | F22: =SUM(F20:F21) -> -54847 | G22: =SUM(G20:G21) -> -57467 | H22: =SUM(H20:H21) -> -62151 | I22: =SUM(I20:I21) -> -67043.537 | J22: =SUM(J20:J21) -> -72272.933 | K22: =SUM(K20:K21) -> -78199.313 | L22: =SUM(L20:L21) -> -84846.255 | M22: =SUM(M20:M21) -> -92482.418 | ... O22: =SUM(O20:O21) -> -103468.17
F24: =F17+F22 -> 114301 | G24: =G17+G22 -> 123216 | H24: =H17+H22 -> 133050 | I24: =I17+I22 -> 144367.08 | J24: =J17+J22 -> 158518.63 | K24: =K17+K22 -> 174123.8 | L24: =L17+L22 -> 192318.18 | M24: =M17+M22 -> 218258.51 | ... O24: =O17+O22 -> 248323.62
B26: Other income/(expense), net | F26: -565 | G26: 269 | H26: -321 | I26: 0 | J26: 0 | K26: 0 | L26: 0 | M26: 0 | N26: 0 | O26: 0
B28: Income before provision for taxes | F28: =F24+F26 -> 113736 | G28: =G24+G26 -> 123485 | H28: =H24+H26 -> 132729 | I28: =I24+I26 -> 144367.08 | J28: =J24+J26 -> 158518.63 | K28: =K24+K26 -> 174123.8 | L28: =L24+L26 -> 192318.18 | M28: =M24+M26 -> 218258.51 | ... O28: =O24+O26 -> 248323.62
B30: Provision for income taxes | F30: -16741 | G30: -29749 | H30: -20719 | I30: =I28*Inputs!$F$37*-1 -> -22376.898 | J30: =J28*Inputs!$F$37*-1 -> -24570.388 | K30: =K28*Inputs!$F$37*-1 -> -26989.19 | L30: =L28*Inputs!$F$37*-1 -> -29809.318 | M30: =M28*Inputs!$F$37*-1 -> -33830.069 | N30: =N28*Inputs!$F$37*-1 -> -37447.067 | O30: =O28*Inputs!$F$37*-1 -> -38490.16
B32: Net income | F32: =F28+F30 -> 96995 | G32: =G28+G30 -> 93736 | H32: =H28+H30 -> 112010 | I32: =I28+I30 -> 121990.19 | J32: =J28+J30 -> 133948.24 | K32: =K28+K30 -> 147134.61 | L32: =L28+L30 -> 162508.86 | M32: =M28+M30 -> 184428.44 | ... O32: =O28+O30 -> 209833.46
B38: Balance Sheet
B40: All figures in USD millions unless stated | F40: 2023 | G40: 2024 | H40: 2025 | I40: 2026F | J40: 2027F | K40: 2028F | L40: 2029F | M40: 2030F | N40: 2031F | O40: term
B42: Assets
B44: Current assets
B45: Cash and cash equivalents | F45: 29965 | G45: 29943 | H45: 35934 | I45: =I135 -> 46263.76 | J45: =J135 -> 64863.416 | K45: =K135 -> 96682.189 | L45: =L135 -> 143590.91 | M45: =M135 -> 210906.52 | N45: =N135 -> 299246.93 | O45: =O135 -> 392923.81
B46: Marketable securities | F46: 31590 | G46: 35228 | H46: 18763 | I46: 18763 | J46: 18763 | K46: 18763 | L46: 18763 | M46: 18763 | N46: 18763 | O46: 18763
B47: Accounts receivable, net | F47: 29508 | G47: 33410 | H47: 39777 | I47: ='Supporting schedules & calc'!K164 -> 39185.264 | J47: ='Supporting schedules & calc'!L164 -> 42241.714 | K47: ='Supporting schedules & calc'!M164 -> 45705.535 | L47: ='Supporting schedules & calc'!N164 -> 49590.505 | M47: ='Supporting schedules & calc'!O164 -> 54053.651 | N47: ='Supporting schedules & calc'!P164 -> 58999.56 | O47: ='Supporting schedules & calc'!Q164 -> 60474.549
B48: Inventories | F48: 6331 | G48: 7286 | H48: 5718 | I48: ='Supporting schedules & calc'!K165 -> 5807.9908 | J48: ='Supporting schedules & calc'!L165 -> 6189.7312 | K48: ='Supporting schedules & calc'!M165 -> 6633.0157 | L48: ='Supporting schedules & calc'!N165 -> 7113.1381 | M48: ='Supporting schedules & calc'!O165 -> 7540.4843 | N48: ='Supporting schedules & calc'!P165 -> 8147.4705 | O48: ='Supporting schedules & calc'!Q165 -> 8334.1488
B49: Other current assets | F49: 46172 | G49: 47120 | H49: 47765 | I49: 47765 | J49: 47765 | K49: 47765 | L49: 47765 | M49: 47765 | N49: 47765 | O49: 47765
B50: Total current assets | F50: =SUM(F45:F49) -> 143566 | G50: =SUM(G45:G49) -> 152987 | H50: =SUM(H45:H49) -> 147957 | I50: =SUM(I45:I49) -> 157785.01 | J50: =SUM(J45:J49) -> 179822.86 | K50: =SUM(K45:K49) -> 215548.74 | L50: =SUM(L45:L49) -> 266822.55 | M50: =SUM(M45:M49) -> 339028.66 | ... O50: =SUM(O45:O49) -> 528260.51
B52: Non-current assets
B53: Property, plant and equipment, net | F53: 43715 | G53: 45680 | H53: 49834 | I53: ='Supporting schedules & calc'!K185 -> 50727.914 | J53: ='Supporting schedules & calc'!L185 -> 51691.553 | K53: ='Supporting schedules & calc'!M185 -> 52734.21 | L53: ='Supporting schedules & calc'!N185 -> 53865.494 | M53: ='Supporting schedules & calc'!O185 -> 55098.593 | N53: ='Supporting schedules & calc'!P185 -> 56444.52 | O53: ='Supporting schedules & calc'!Q185 -> 56444.52
B54: Other non-current assets | F54: 165302 | G54: 166313 | H54: 161450 | I54: 161450 | J54: 161450 | K54: 161450 | L54: 161450 | M54: 161450 | N54: 161450 | O54: 161450
B55: Total non-current assets | F55: =SUM(F53:F54) -> 209017 | G55: =SUM(G53:G54) -> 211993 | H55: =SUM(H53:H54) -> 211284 | I55: =SUM(I53:I54) -> 212177.91 | J55: =SUM(J53:J54) -> 213141.55 | K55: =SUM(K53:K54) -> 214184.21 | L55: =SUM(L53:L54) -> 215315.49 | M55: =SUM(M53:M54) -> 216548.59 | ... O55: =SUM(O53:O54) -> 217894.52
B57: Total assets | F57: =F50+F55 -> 352583 | G57: =G50+G55 -> 364980 | H57: =H50+H55 -> 359241 | I57: =I50+I55 -> 369962.93 | J57: =J50+J55 -> 392964.41 | K57: =K50+K55 -> 429732.95 | L57: =L50+L55 -> 482138.04 | M57: =M50+M55 -> 555577.25 | ... O57: =O50+O55 -> 746155.03
B61: Liabilities
B63: Current liabilities
B64: Accounts payable | F64: 62611 | G64: 68960 | H64: 69860 | I64: ='Supporting schedules & calc'!K163 -> 74213.216 | J64: ='Supporting schedules & calc'!L163 -> 79091.01 | K64: ='Supporting schedules & calc'!M163 -> 84755.201 | L64: ='Supporting schedules & calc'!N163 -> 90890.098 | M64: ='Supporting schedules & calc'!O163 -> 96350.632 | N64: ='Supporting schedules & calc'!P163 -> 104106.57 | O64: ='Supporting schedules & calc'!Q163 -> 106491.9
B65: Other current liabilities | F65: 66890 | G65: 86553 | H65: 75442 | I65: 75442 | J65: 75442 | K65: 75442 | L65: 75442 | M65: 75442 | N65: 75442 | O65: 75442
B66: Current portion of debt | F66: 15807 | G66: 20879 | H66: 20329 | I66: 20329 | J66: 20329 | K66: 20329 | L66: 20329 | M66: 20329 | N66: 20329 | O66: 20329
B67: Total current liabilities | F67: =SUM(F64:F66) -> 145308 | G67: =SUM(G64:G66) -> 176392 | H67: =SUM(H64:H66) -> 165631 | I67: =SUM(I64:I66) -> 169984.22 | J67: =SUM(J64:J66) -> 174862.01 | K67: =SUM(K64:K66) -> 180526.2 | L67: =SUM(L64:L66) -> 186661.1 | M67: =SUM(M64:M66) -> 192121.63 | ... O67: =SUM(O64:O66) -> 202262.9
B69: Non-current liabilities
...

Sheet Supporting schedules & calc
B3: Supporting schedules & calculations
B6: Revenue forecasts
D8: 2015 | E8: 2016 | F8: 2017 | G8: 2018 | H8: 2019 | I8: 2020 | J8: 2021 | K8: 2022 | L8: 2023 | M8: 2024 | N8: 2025 | O8: 2026 | P8: 2027 | Q8: 2028 | R8: 2029 | S8: 2030 | T8: 2031
B11: Revenue growth % | E11: =E21/D21-1 -> -0.077342062 | F11: =F21/E21-1 -> 0.063045182 | G11: =G21/F21-1 -> 0.15861958 | H11: =H21/G21-1 -> -0.020410776 | I11: =I21/H21-1 -> 0.055120804 | J11: =J21/I21-1 -> 0.33259385 | K11: =K21/J21-1 -> 0.077937876 | L11: =L21/K21-1 -> -0.028004605 | ... T11: =T21/S21-1 -> 0.041965973
B15: Iphone | D15: 155041 | E15: 136700 | F15: 141319 | G15: 164888 | H15: 142381 | I15: 137781 | J15: 191973 | K15: 205489 | L15: 200583 | M15: 201183 | N15: 209586 | O15: =_xlfn.FORECAST.ETS(O$8,$D15:$N15,$D$8:$N$8) -> 217557.25 | P15: =_xlfn.FORECAST.ETS(P$8,$D15:$N15,$D$8:$N$8) -> 225158.59 | Q15: =_xlfn.FORECAST.ETS(Q$8,$D15:$N15,$D$8:$N$8) -> 232759.94 | R15: =_xlfn.FORECAST.ETS(R$8,$D15:$N15,$D$8:$N$8) -> 240361.28 | S15: =_xlfn.FORECAST.ETS(S$8,$D15:$N15,$D$8:$N$8) -> 247962.63 | T15: =_xlfn.FORECAST.ETS(T$8,$D15:$N15,$D$8:$N$8) -> 255563.98
B16: Ipad | D16: 23227 | E16: 20628 | F16: 19222 | G16: 25198 | H16: 25740 | I16: 28622 | J16: 35190 | K16: 40177 | L16: 29357 | M16: 29984 | N16: 33708 | O16: =_xlfn.FORECAST.ETS(O$8,$D16:$N16,$D$8:$N$8) -> 36594.579 | P16: =_xlfn.FORECAST.ETS(P$8,$D16:$N16,$D$8:$N$8) -> 38035.745 | Q16: =_xlfn.FORECAST.ETS(Q$8,$D16:$N16,$D$8:$N$8) -> 39476.911 | R16: =_xlfn.FORECAST.ETS(R$8,$D16:$N16,$D$8:$N$8) -> 40918.077 | S16: =_xlfn.FORECAST.ETS(S$8,$D16:$N16,$D$8:$N$8) -> 42359.243 | T16: =_xlfn.FORECAST.ETS(T$8,$D16:$N16,$D$8:$N$8) -> 43800.409
B17: Mac | D17: 25471 | E17: 22831 | F17: 25850 | G17: 18380 | H17: 21280 | I17: 23724 | J17: 31862 | K17: 29292 | L17: 28300 | M17: 26694 | N17: 28023 | O17: =_xlfn.FORECAST.ETS(O$8,$D17:$N17,$D$8:$N$8) -> 29407.328 | P17: =_xlfn.FORECAST.ETS(P$8,$D17:$N17,$D$8:$N$8) -> 30014.158 | Q17: =_xlfn.FORECAST.ETS(Q$8,$D17:$N17,$D$8:$N$8) -> 30620.987 | R17: =_xlfn.FORECAST.ETS(R$8,$D17:$N17,$D$8:$N$8) -> 31227.816 | S17: =_xlfn.FORECAST.ETS(S$8,$D17:$N17,$D$8:$N$8) -> 31834.646 | T17: =_xlfn.FORECAST.ETS(T$8,$D17:$N17,$D$8:$N$8) -> 32441.475
B18: Services | D18: 19909 | E18: 24348 | F18: 29980 | G18: 39748 | H18: 46291 | I18: 53768 | J18: 68425 | K18: 78129 | L18: 85200 | M18: 96169 | N18: 109158 | O18: =_xlfn.FORECAST.ETS(O$8,$D18:$N18,$D$8:$N$8) -> 119423.5 | P18: =_xlfn.FORECAST.ETS(P$8,$D18:$N18,$D$8:$N$8) -> 129696.25 | Q18: =_xlfn.FORECAST.ETS(Q$8,$D18:$N18,$D$8:$N$8) -> 139968.99 | R18: =_xlfn.FORECAST.ETS(R$8,$D18:$N18,$D$8:$N$8) -> 150241.74 | S18: =_xlfn.FORECAST.ETS(S$8,$D18:$N18,$D$8:$N$8) -> 160514.48 | T18: =_xlfn.FORECAST.ETS(T$8,$D18:$N18,$D$8:$N$8) -> 170787.23
B19: Other Products | D19: 10067 | E19: 11132 | F19: 12863 | G19: 17381 | H19: 24482 | I19: 30620 | J19: 38367 | K19: 41241 | L19: 39845 | M19: 37005 | N19: 35686 | O19: 36940 | P19: 39030 | Q19: 40870 | R19: 42450 | S19: 44115 | T19: 46300
B21: Total revenue | D21: =SUM(D15:D19) -> 233715 | E21: =SUM(E15:E19) -> 215639 | F21: =SUM(F15:F19) -> 229234 | G21: =SUM(G15:G19) -> 265595 | H21: =SUM(H15:H19) -> 260174 | I21: =SUM(I15:I19) -> 274515 | J21: =SUM(J15:J19) -> 365817 | K21: =SUM(K15:K19) -> 394328 | ... T21: =SUM(T15:T19) -> 548893.09
E25: =E15/D15-1 -> -0.11829774 | F25: =F15/E15-1 -> 0.03378932 | G25: =G15/F15-1 -> 0.16677871 | H25: =H15/G15-1 -> -0.13649871 | I25: =I15/H15-1 -> -0.032307682 | J25: =J15/I15-1 -> 0.39331983 | K25: =K15/J15-1 -> 0.070405734 | L25: =L15/K15-1 -> -0.023874757 | ... T25: =T15/S15-1 -> 0.030655208
B27: Ipad
B28: Growth % | E28: =E16/D16-1 -> -0.11189564 | F28: =F16/E16-1 -> -0.068159783 | G28: =G16/F16-1 -> 0.31089377 | H28: =H16/G16-1 -> 0.021509644 | I28: =I16/H16-1 -> 0.11196581 | J28: =J16/I16-1 -> 0.22947383 | K28: =K16/J16-1 -> 0.1417164 | L28: =L16/K16-1 -> -0.26930831 | ... T28: =T16/S16-1 -> 0.034022471
B30: Mac
B31: Growth % | E31: =E17/D17-1 -> -0.10364729 | F31: =F17/E17-1 -> 0.13223249 | G31: =G17/F17-1 -> -0.28897485 | H31: =H17/G17-1 -> 0.1577802 | I31: =I17/H17-1 -> 0.11484962 | J31: =J17/I17-1 -> 0.34302816 | K31: =K17/J17-1 -> -0.080660348 | L31: =L17/K17-1 -> -0.033865902 | ... T31: =T17/S17-1 -> 0.019061915
B33: Services
B34: Growth % | E34: =E18/D18-1 -> 0.22296449 | F34: =F18/E18-1 -> 0.23131263 | G34: =G18/F18-1 -> 0.32581721 | H34: =H18/G18-1 -> 0.16461206 | I34: =I18/H18-1 -> 0.16152168 | J34: =J18/I18-1 -> 0.27259708 | K34: =K18/J18-1 -> 0.14181951 | L34: =L18/K18-1 -> 0.090504166 | ... T34: =T18/S18-1 -> 0.063998871
B36: Other Products
B37: Growth % | E37: =E19/D19-1 -> 0.1057912 | F37: =F19/E19-1 -> 0.15549766 | G37: =G19/F19-1 -> 0.35123999 | H37: =H19/G19-1 -> 0.40854957 | I37: =I19/H19-1 -> 0.25071481 | J37: =J19/I19-1 -> 0.25300457 | K37: =K19/J19-1 -> 0.074908124 | L37: =L19/K19-1 -> -0.03384981 | ... T37: =T19/S19-1 -> 0.049529638
B39: Total
B40: Growth % | E40: =E21/D21-1 -> -0.077342062 | F40: =F21/E21-1 -> 0.063045182 | G40: =G21/F21-1 -> 0.15861958 | H40: =H21/G21-1 -> -0.020410776 | I40: =I21/H21-1 -> 0.055120804 | J40: =J21/I21-1 -> 0.33259385 | K40: =K21/J21-1 -> 0.077937876 | L40: =L21/K21-1 -> -0.028004605 | ... T40: =T21/S21-1 -> 0.041965973
B76: Revenue Scenarios
D81: 2026F | E81: 2027F | F81: 2028F | G81: 2029F | H81: 2030F | I81: 2031F
B85: Bear case | D85: 0.045 | E85: 0.032 | F85: 0.028 | G85: 0.015 | H85: 0.008 | I85: 0.001
B86: Base case | D86: 0.0571 | E86: 0.05 | F86: 0.0471 | G86: 0.0445 | H86: 0.0427 | I86: 0.042
B87: Bull case | D87: 0.074 | E87: 0.078 | F87: 0.082 | G87: 0.085 | H87: 0.09 | I87: 0.0915
B98: Cost forecast
D100: 2015 | E100: 2016 | F100: 2017 | G100: 2018 | H100: 2019 | I100: 2020 | J100: 2021 | K100: 2022 | L100: 2023 | M100: 2024 | N100: 2025 | O100: 2026 | P100: 2027 | Q100: 2028 | R100: 2029 | S100: 2030 | T100: 2031
B103: Revenue | D103: =D21 -> 233715 | E103: =E21 -> 215639 | F103: =F21 -> 229234 | G103: =G21 -> 265595 | H103: =H21 -> 260174 | I103: =I21 -> 274515 | J103: =J21 -> 365817 | K103: =K21 -> 394328 | ... T103: =T21 -> 548893.09
B105: Gross margin %
B106: Products | D106: - | E106: - | F106: - | G106: 0.344 | H106: 0.322 | I106: 0.315 | J106: 0.315 | K106: 0.353 | L106: 0.363 | M106: 0.372 | N106: 0.368 | O106: 0.372 | P106: 0.379 | Q106: 0.39 | R106: 0.396 | S106: 0.411 | T106: 0.42
B107: Services | D107: - | E107: - | F107: - | G107: 0.608 | H107: 0.637 | I107: 0.66 | J107: 0.66 | K107: 0.697 | L107: 0.717 | M107: 0.739 | N107: 0.754 | O107: 0.757 | P107: 0.76 | Q107: 0.764 | R107: 0.769 | S107: 0.771 | T107: 0.775
B108: Total gross margin % | D108: 0.401 | E108: 0.391 | F108: 0.385 | G108: 0.383 | H108: 0.378 | I108: 0.382 | J108: 0.382 | K108: 0.418 | L108: 0.433 | M108: 0.462 | N108: 0.469 | O108: 0.473 | P108: 0.479 | Q108: 0.484 | R108: 0.49 | S108: 0.504 | T108: 0.509
B111: Operating Expenses
B112: R&D | D112: 0.03 | E112: 0.05 | F112: 0.05 | G112: 0.05 | H112: 0.06 | I112: 0.07 | J112: 0.06 | K112: 0.07 | L112: 0.08 | M112: 0.08 | N112: 0.08 | O112: 0.08 | P112: 0.08 | Q112: 0.08 | R112: 0.08 | S112: 0.08 | T112: 0.08
B113: SG&A | D113: 0.06 | E113: 0.07 | F113: 0.07 | G113: 0.06 | H113: 0.07 | I113: 0.07 | J113: 0.06 | K113: 0.06 | L113: 0.07 | M113: 0.07 | N113: 0.07 | O113: 0.07 | P113: 0.07 | Q113: 0.07 | R113: 0.07 | S113: 0.07 | T113: 0.07
B114: Total % of revenue | D114: 0.1 | E114: 0.11 | F114: 0.12 | G114: 0.12 | H114: 0.13 | I114: 0.14 | J114: 0.12 | K114: 0.13 | L114: 0.14 | M114: 0.15 | N114: 0.15 | O114: 0.15 | P114: 0.15 | Q114: 0.15 | R114: 0.15 | S114: 0.15 | T114: 0.15
B147: Working capital schedule
B149: All figures in USD millions unless stated | H149: 2023 | I149: 2024 | J149: 2025 | K149: 2026F | L149: 2027F | M149: 2028F | N149: 2029F | O149: 2030F | P149: 2031F | Q149: term
B153: Days in period | H153: 365 | I153: 365 | J153: 365 | K153: 365 | L153: 365 | M153: 365 | N153: 365 | O153: 365 | P153: 365 | Q153: 365
...
